Using TensorFlow backend.
WARNING:root:Running with configuration:
{'alter_retrain_full_training': 0,
 'attack_succ_threshold': 0.85,
 'benign_poison_ratio': 0.001,
 'classifier': 'mlp',
 'clean_ratio': 0.02,
 'convert_mask_to_binary': 0,
 'dataset': 'apg',
 'debug': True,
 'delta_size': 30,
 'device': '1',
 'lambda_1': 0.001,
 'limited_data': 1.0,
 'mask_expand_type': 0,
 'mask_optim_step': 30,
 'mask_size_upperbound': 0,
 'max_iter': 40,
 'mlp_batch_size': 128,
 'mlp_dropout': 0.2,
 'mlp_epochs': 30,
 'mlp_hidden': '1024',
 'mlp_lr': 0.001,
 'mntd_half_training': 0,
 'num_of_train_batches': 5,
 'num_triggers': 1,
 'param_v': 1.0,
 'poison_mal_benign_rate': 0.0,
 'random_state': 42,
 'realizable_only': 1,
 'remain_benign_rate': 1.0,
 'setting': 'realizable-2171',
 'subset_benign_rate': 5.0,
 'subset_family': 'mobisec',
 'use_last_weight': 1}
2025-02-27 18:38:24.206447: E tensorflow/stream_executor/cuda/cuda_driver.cc:300] failed call to cuInit: CUDA_ERROR_NO_DEVICE: no CUDA-capable device is detected
DEBUG: 02-27 18:38:24: models.py:242 * 128522746165056 Loading model from models/apg/mlp/mlp_10000-1024-1_lr0.001_b128_e30_d0.2_r42.p...
INFO: 02-27 18:38:26: subset_backdoor_main.py:450 * 128522746165056 X_train: (100187, 10000), X_test: (49347, 10000)
INFO: 02-27 18:38:26: subset_backdoor_main.py:451 * 128522746165056 y_train: (100187,), y_test: (49347,)
INFO: 02-27 18:38:26: subset_backdoor_main.py:452 * 128522746165056 y_train: Counter({0: 90288, 1: 9899}), y_test: Counter({0: 44471, 1: 4876})
INFO: 02-27 18:38:28: subset_backdoor_main.py:335 * 128522746165056 subset size: 57
DEBUG: 02-27 18:38:28: subset_backdoor_main.py:336 * 128522746165056 subset_idx_array first 20: [ 8573 10883 15767 21281 24446 25511 27326 29350 30038 30323 30379 35270
 35652 36621 37036 39068 39338 40862 43975 44627]
DEBUG: 02-27 18:38:31: subset_backdoor_main.py:356 * 128522746165056 subset_train_idxs first 20 (maybe < 20): [31654, 25805, 2431, 14870, 43448, 72040, 4119, 4876, 49884, 13393, 58717, 23786, 68655, 83140, 32691, 64643, 4352, 1495, 47262, 94023]
DEBUG: 02-27 18:38:31: subset_backdoor_main.py:357 * 128522746165056 subset_test_idxs first 20 (maybe < 20): [2381, 24652, 28162, 33242, 3820, 25949, 24918, 44519, 2478, 33926, 24445, 29574, 15140, 25119, 48317, 22483, 27884, 15533]
INFO: 02-27 18:38:31: subset_backdoor_main.py:361 * 128522746165056 X_subset: (57, 10000), type: <class 'scipy.sparse.csr.csr_matrix'>
DEBUG: 02-27 18:38:31: subset_backdoor_main.py:364 * 128522746165056 no. of samples of subset in training: 39, from testing: 18
DEBUG: 02-27 18:38:31: attrs.py:77 * 128522746165056 Creating converter from 3 to 5
Traceback (most recent call last):
  File "subset_backdoor_main.py", line 932, in <module>
    main()
  File "subset_backdoor_main.py", line 131, in main
    X_test_remain_mal_tp, X_test_benign_tn = separate_subset_malware(args, dataset, clf, random_state, subset_family)
  File "subset_backdoor_main.py", line 367, in separate_subset_malware
    clean_model = load_model(CLEAN_MODEL_PATH)
  File "/home/puya/anaconda3/envs/backdoor/lib/python3.6/site-packages/keras/engine/saving.py", line 458, in load_wrapper
    return load_function(*args, **kwargs)
  File "/home/puya/anaconda3/envs/backdoor/lib/python3.6/site-packages/keras/engine/saving.py", line 550, in load_model
    model = _deserialize_model(h5dict, custom_objects, compile)
  File "/home/puya/anaconda3/envs/backdoor/lib/python3.6/site-packages/keras/engine/saving.py", line 242, in _deserialize_model
    model_config = json.loads(model_config.decode('utf-8'))
AttributeError: 'str' object has no attribute 'decode'
