Using TensorFlow backend.
WARNING:root:Running with configuration:
{'alter_retrain_full_training': 0,
 'attack_succ_threshold': 0.85,
 'benign_poison_ratio': 0.001,
 'classifier': 'mlp',
 'clean_ratio': 0.02,
 'convert_mask_to_binary': 0,
 'dataset': 'apg',
 'debug': True,
 'delta_size': 30,
 'device': '7',
 'lambda_1': 0.001,
 'limited_data': 1.0,
 'mask_expand_type': 0,
 'mask_optim_step': 30,
 'mask_size_upperbound': 0,
 'max_iter': 40,
 'mlp_batch_size': 128,
 'mlp_dropout': 0.2,
 'mlp_epochs': 30,
 'mlp_hidden': '1024',
 'mlp_lr': 0.001,
 'mntd_half_training': 0,
 'num_of_train_batches': 5,
 'num_triggers': 1,
 'param_v': 1.0,
 'poison_mal_benign_rate': 0.0,
 'random_state': 42,
 'realizable_only': 0,
 'remain_benign_rate': 1.0,
 'setting': '',
 'subset_benign_rate': 5.0,
 'subset_family': 'leadbolt',
 'use_last_weight': 1}
2025-02-27 18:39:45.830234: E tensorflow/stream_executor/cuda/cuda_driver.cc:300] failed call to cuInit: CUDA_ERROR_NO_DEVICE: no CUDA-capable device is detected
DEBUG: 02-27 18:39:45: models.py:242 * 139677577574208 Loading model from models/apg/mlp/mlp_10000-1024-1_lr0.001_b128_e30_d0.2_r42.p...
INFO: 02-27 18:39:48: subset_backdoor_main.py:450 * 139677577574208 X_train: (100187, 10000), X_test: (49347, 10000)
INFO: 02-27 18:39:48: subset_backdoor_main.py:451 * 139677577574208 y_train: (100187,), y_test: (49347,)
INFO: 02-27 18:39:48: subset_backdoor_main.py:452 * 139677577574208 y_train: Counter({0: 90288, 1: 9899}), y_test: Counter({0: 44471, 1: 4876})
INFO: 02-27 18:39:50: subset_backdoor_main.py:335 * 139677577574208 subset size: 222
DEBUG: 02-27 18:39:50: subset_backdoor_main.py:336 * 139677577574208 subset_idx_array first 20: [ 664  891 1783 2986 3973 4179 4436 4652 5262 5439 5543 5733 7146 7452
 7614 7710 8894 9275 9316 9450]
DEBUG: 02-27 18:40:06: subset_backdoor_main.py:356 * 139677577574208 subset_train_idxs first 20 (maybe < 20): [2792, 41932, 78863, 70592, 948, 79245, 25121, 69083, 36998, 96465, 80830, 36955, 61249, 40959, 34175, 35806, 7921, 70097, 97915, 36139]
DEBUG: 02-27 18:40:06: subset_backdoor_main.py:357 * 139677577574208 subset_test_idxs first 20 (maybe < 20): [13155, 29365, 35548, 27221, 46575, 44856, 29389, 1750, 8585, 48892, 12692, 47871, 48976, 2207, 17112, 13688, 48727, 49027, 19697, 15134]
INFO: 02-27 18:40:06: subset_backdoor_main.py:361 * 139677577574208 X_subset: (222, 10000), type: <class 'scipy.sparse.csr.csr_matrix'>
DEBUG: 02-27 18:40:06: subset_backdoor_main.py:364 * 139677577574208 no. of samples of subset in training: 152, from testing: 70
DEBUG: 02-27 18:40:06: attrs.py:77 * 139677577574208 Creating converter from 3 to 5
Traceback (most recent call last):
  File "problem_space_with_side_effect_fea.py", line 251, in <module>
    main()
  File "problem_space_with_side_effect_fea.py", line 83, in main
    random_state, subset_family)
  File "/home/puya/Desktop/jigsawpuzzle/subset_backdoor_main.py", line 367, in separate_subset_malware
    clean_model = load_model(CLEAN_MODEL_PATH)
  File "/home/puya/anaconda3/envs/backdoor/lib/python3.6/site-packages/keras/engine/saving.py", line 458, in load_wrapper
    return load_function(*args, **kwargs)
  File "/home/puya/anaconda3/envs/backdoor/lib/python3.6/site-packages/keras/engine/saving.py", line 550, in load_model
    model = _deserialize_model(h5dict, custom_objects, compile)
  File "/home/puya/anaconda3/envs/backdoor/lib/python3.6/site-packages/keras/engine/saving.py", line 242, in _deserialize_model
    model_config = json.loads(model_config.decode('utf-8'))
AttributeError: 'str' object has no attribute 'decode'
