Using TensorFlow backend.
WARNING:root:Running with configuration:
{'alter_retrain_full_training': 0,
 'attack_succ_threshold': 0.85,
 'benign_poison_ratio': 0.001,
 'classifier': 'mlp',
 'clean_ratio': 0.02,
 'convert_mask_to_binary': 0,
 'dataset': 'apg',
 'debug': True,
 'delta_size': 30,
 'device': '3',
 'lambda_1': 0.001,
 'limited_data': 1.0,
 'mask_expand_type': 0,
 'mask_optim_step': 30,
 'mask_size_upperbound': 0,
 'max_iter': 40,
 'mlp_batch_size': 128,
 'mlp_dropout': 0.2,
 'mlp_epochs': 30,
 'mlp_hidden': '1024',
 'mlp_lr': 0.001,
 'mntd_half_training': 0,
 'num_of_train_batches': 5,
 'num_triggers': 1,
 'param_v': 1.0,
 'poison_mal_benign_rate': 0.0,
 'random_state': 42,
 'realizable_only': 0,
 'remain_benign_rate': 1.0,
 'setting': '',
 'subset_benign_rate': 5.0,
 'subset_family': 'youmi',
 'use_last_weight': 1}
2025-02-27 18:39:45.347236: E tensorflow/stream_executor/cuda/cuda_driver.cc:300] failed call to cuInit: CUDA_ERROR_NO_DEVICE: no CUDA-capable device is detected
DEBUG: 02-27 18:39:45: models.py:242 * 123720679573312 Loading model from models/apg/mlp/mlp_10000-1024-1_lr0.001_b128_e30_d0.2_r42.p...
INFO: 02-27 18:39:48: subset_backdoor_main.py:450 * 123720679573312 X_train: (100187, 10000), X_test: (49347, 10000)
INFO: 02-27 18:39:48: subset_backdoor_main.py:451 * 123720679573312 y_train: (100187,), y_test: (49347,)
INFO: 02-27 18:39:48: subset_backdoor_main.py:452 * 123720679573312 y_train: Counter({0: 90288, 1: 9899}), y_test: Counter({0: 44471, 1: 4876})
INFO: 02-27 18:39:50: subset_backdoor_main.py:335 * 123720679573312 subset size: 70
DEBUG: 02-27 18:39:50: subset_backdoor_main.py:336 * 123720679573312 subset_idx_array first 20: [  352  5359 13654 16668 16796 16863 16953 17637 19925 21337 22377 22461
 24868 25291 27364 28577 29214 29467 33292 33468]
DEBUG: 02-27 18:39:57: subset_backdoor_main.py:356 * 123720679573312 subset_train_idxs first 20 (maybe < 20): [16959, 18546, 62081, 56576, 76310, 90522, 2456, 28510, 84573, 3843, 14601, 52752, 13366, 26011, 8337, 43135, 77964, 44957, 81896, 75543]
DEBUG: 02-27 18:39:57: subset_backdoor_main.py:357 * 123720679573312 subset_test_idxs first 20 (maybe < 20): [36366, 6383, 21955, 27513, 24221, 2517, 42881, 5903, 25278, 37119, 34549, 16884, 10851, 23596, 18034, 14717, 42437, 45330, 6069, 18258]
INFO: 02-27 18:39:57: subset_backdoor_main.py:361 * 123720679573312 X_subset: (70, 10000), type: <class 'scipy.sparse.csr.csr_matrix'>
DEBUG: 02-27 18:39:58: subset_backdoor_main.py:364 * 123720679573312 no. of samples of subset in training: 49, from testing: 21
DEBUG: 02-27 18:39:58: attrs.py:77 * 123720679573312 Creating converter from 3 to 5
Traceback (most recent call last):
  File "problem_space_with_side_effect_fea.py", line 251, in <module>
    main()
  File "problem_space_with_side_effect_fea.py", line 83, in main
    random_state, subset_family)
  File "/home/puya/Desktop/jigsawpuzzle/subset_backdoor_main.py", line 367, in separate_subset_malware
    clean_model = load_model(CLEAN_MODEL_PATH)
  File "/home/puya/anaconda3/envs/backdoor/lib/python3.6/site-packages/keras/engine/saving.py", line 458, in load_wrapper
    return load_function(*args, **kwargs)
  File "/home/puya/anaconda3/envs/backdoor/lib/python3.6/site-packages/keras/engine/saving.py", line 550, in load_model
    model = _deserialize_model(h5dict, custom_objects, compile)
  File "/home/puya/anaconda3/envs/backdoor/lib/python3.6/site-packages/keras/engine/saving.py", line 242, in _deserialize_model
    model_config = json.loads(model_config.decode('utf-8'))
AttributeError: 'str' object has no attribute 'decode'
